<?xml version="1.0"?>
<robot name="robot">

    <!-- Define materials directly -->
    <material name="white">
        <color rgba="1 1 1 1"/>
    </material>
    <material name="orange">
        <color rgba="1 0.3 0.1 1"/>
    </material>
    <material name="blue">
        <color rgba="0.2 0.2 1 1"/>
    </material>

    <!-- This first link called "world" is empty -->
    <link name="world"></link>


    <!-- slider_joint lets slider_link move back and forth along the top of the base in one dimension. -->
    <joint name="slider_joint" type="revolute">
        <origin xyz="0 0 0" rpy="0 0 0"/>
        <parent link="world"/>
        <child link="slider_link"/>
        <axis xyz="0 0 1"/>
        <limit lower="-1.5708" upper="1.5708" velocity="100" effort="100"/>  
    </joint>

    <!-- slider_link is the box skimming across the top of the base -->
    <link name="slider_link">
        <visual>
            <origin xyz="0 0 0.075" rpy="0 0 0"/>
            <geometry>
                <box size="0.5 0.25 0.15" />
            </geometry>
            <material name="blue" />
        </visual>
        <collision>
            <origin xyz="0 0 0.075" rpy="0 0 0"/>
            <geometry>
                <box size="0.5 0.25 0.15" />
            </geometry>
        </collision>
        <inertial>
            <origin xyz="0 0 0.075" rpy="0 0 0"/>
            <mass value="0.5" />
            <inertia ixx="0.0013" ixy="0.0" ixz="0.0" iyy="0.0027" iyz="0.0" izz="0.0004" />
        </inertial>
    </link>

    <!-- arm_joint describes the rotation of the arm -->
    <joint name="arm_joint" type="revolute">
        <origin xyz="0.25 0 0.15" rpy="0 0 0"/>
        <parent link="slider_link"/>
        <child link="arm_link"/>
        <axis xyz="0 -1 0"/>
        <limit lower="-1.5708" upper="1.5708" velocity="100" effort="100"/> 
    </joint>

    <!-- arm_link describes the arm -->
    <link name="arm_link">
        <visual>
            <origin xyz="0.5 0 0" rpy="0 1.5708 0"/>
            <geometry>                
                <cylinder length="1.0" radius="0.1" />
            </geometry>
            <material name="orange" />
        </visual>
        <collision>
            <origin xyz="0.5 0 0" rpy="0 1.5708 0"/>
            <geometry>
                <cylinder length="1.0" radius="0.1" />
            </geometry>
        </collision>
        <inertial>
            <origin xyz="0.5 0 0" rpy="0 1.5708 0"/>
            <mass value="1.0" />
            <inertia ixx="0.0083" ixy="0.0" ixz="0.0" iyy="0.0083" iyz="0.0" izz="0.01" />
        </inertial>
    </link>

    <!-- camera_joint describes where the camera is relative to the arm -->
    <joint name="camera_joint" type="fixed">
        <origin xyz="1.0 0 0.175" rpy="0 0 0"/>
        <parent link="arm_link"/>
        <child link="camera_link"/>        
    </joint>

    <!-- camera_link describes the camera at the end of the arm -->
    <link name="camera_link">
        <visual>
            <origin xyz="-0.03 0 0" rpy="0 0 0"/>
            <geometry>
                <box size="0.06 0.15 0.15" />
            </geometry>
            <material name="white" />
        </visual>
        <visual>
            <origin xyz="0.03 0 0" rpy="0 1.5708 0"/>
            <geometry>
                <cylinder length="0.06" radius="0.04" />
            </geometry>
            <material name="blue" />
        </visual>
        <collision>
            <origin xyz="0.0 0 0" rpy="0 0 0"/>
            <geometry>
                <box size="0.12 0.15 0.15" />
            </geometry>
        </collision>
        <inertial>
            <origin xyz="0.0 0 0" rpy="0 0 0"/>
            <mass value="0.1" />
            <inertia ixx="0.0001" ixy="0.0" ixz="0.0" iyy="0.0001" iyz="0.0" izz="0.0001" />
        </inertial>
    </link>

</robot>
